Workbook

Sheet Sheet1
A1: =VLOOKUP(A3,Sheet2!$A$1:$A$135,1,FALSE) -> #N/A | B1: =IFERROR(VLOOKUP(B3,Sheet2!$A$1:$A$135,1,FALSE),"Ignore Field") -> AgentName | C1: =IFERROR(VLOOKUP(C3,Sheet2!$A$1:$A$135,1,FALSE),"Ignore Field") -> BusinessName | D1: =IFERROR(VLOOKUP(D3,Sheet2!$A$1:$A$135,1,FALSE),"Ignore Field") -> FirstName | E1: =IFERROR(VLOOKUP(E3,Sheet2!$A$1:$A$135,1,FALSE),"Ignore Field") -> MiddleName | F1: =IFERROR(VLOOKUP(F3,Sheet2!$A$1:$A$135,1,FALSE),"Ignore Field") -> LastName | G1: =IFERROR(VLOOKUP(G3,Sheet2!$A$1:$A$135,1,FALSE),"Ignore Field") -> Prefix | H1: =IFERROR(VLOOKUP(H3,Sheet2!$A$1:$A$135,1,FALSE),"Ignore Field") -> Suffix | I1: =IFERROR(VLOOKUP(I3,Sheet2!$A$1:$A$135,1,FALSE),"Ignore Field") -> DoB | ... K1: =IFERROR(VLOOKUP(K3,Sheet2!$A$1:$A$135,1,FALSE),"Ignore Field") -> PreferredLanguage | L1: refer Channel Management | M1: refer Channel Management | N1: refer Channel Management | O1: =IFERROR(VLOOKUP(O3,Sheet2!$A$1:$A$135,1,FALSE),"Ignore Field") -> AgentLevel | P1: =IFERROR(VLOOKUP(P3,Sheet2!$A$1:$A$135,1,FALSE),"Ignore Field") -> StaffCode | Q1: =IFERROR(VLOOKUP(Q3,Sheet2!$A$1:$A$135,1,FALSE),"Ignore Field") -> Supervisor_Code | R1: =IFERROR(VLOOKUP(R3,Sheet2!$A$1:$A$135,1,FALSE),"Ignore Field") -> ContractedDate | S1: =IFERROR(VLOOKUP(S3,Sheet2!$A$1:$A$135,1,FALSE),"Ignore Field") -> AgentStatusCode | T1: =IFERROR(VLOOKUP(T3,Sheet2!$A$1:$A$135,1,FALSE),"Ignore Field") -> StatusDate | U1: =IFERROR(VLOOKUP(U3,Sheet2!$A$1:$A$135,1,FALSE),"Ignore Field") -> IsLicensed | V1: =IFERROR(VLOOKUP(V3,Sheet2!$A$1:$A$135,1,FALSE),"Ignore Field") -> MaskedPanNumber | ... BO1: =IFERROR(VLOOKUP(BO3,Sheet2!$A$1:$A$135,1,FALSE),"Ignore Field") -> HRDoj | BP1: =IFERROR(BN11VLOOKUP(BP3,Sheet2!$A$1:$A$135,1,FALSE),"Ignore Field") -> Ignore Field | BQ1: =IFERROR(VLOOKUP(BQ3,Sheet2!$A$1:$A$135,1,FALSE),"Ignore Field") -> HSecPolicyTrngDate | BR1: =IFERROR(VLOOKUP(BR3,Sheet2!$A$1:$A$135,1,FALSE),"Ignore Field") -> ITSecPolicyTrngDate | BS1: =IFERROR(VLOOKUP(BS3,Sheet2!$A$1:$A$135,1,FALSE),"Ignore Field") -> NPSTrngCompletionDate | BT1: =IFERROR(VLOOKUP(BT3,Sheet2!$A$1:$A$135,1,FALSE),"Ignore Field") -> WhistleBlowerTrngDate | BU1: =IFERROR(VLOOKUP(BU3,Sheet2!$A$1:$A$135,1,FALSE),"Ignore Field") -> GovPolicyTrngDate | BV1: =IFERROR(VLOOKUP(BV3,Sheet2!$A$1:$A$135,1,FALSE),"Ignore Field") -> InductionTrngDate | BW1: =IFERROR(VLOOKUP(BW3,Sheet2!$A$1:$A$135,1,FALSE),"Ignore Field") -> LastWorkingDate | BX1: =IFERROR(VLOOKUP(BX3,Sheet2!$A$1:$A$135,1,FALSE),"Ignore Field") -> LicenseNo | ... CT1: =IFERROR(VLOOKUP(CT3,Sheet2!$A$1:$A$135,1,FALSE),"Ignore Field") -> CountryDesc | CU1: refer Channel Management | CV1: refer Channel Management | CW1: =IFERROR(VLOOKUP(CW3,Sheet2!$A$1:$A$135,1,FALSE),"Ignore Field") -> AgentTypeCodeDesc | CX1: =IFERROR(VLOOKUP(CX3,Sheet2!$A$1:$A$135,1,FALSE),"Ignore Field") -> AgentSubTypeCodeDesc | CY1: =IFERROR(VLOOKUP(CY3,Sheet2!$A$1:$A$135,1,FALSE),"Ignore Field") -> CandidateTypeDesc | CZ1: =IFERROR(VLOOKUP(CZ3,Sheet2!$A$1:$A$135,1,FALSE),"Ignore Field") -> CommissionClassDesc | DA1: =IFERROR(VLOOKUP(DA3,Sheet2!$A$1:$A$135,1,FALSE),"Ignore Field") -> AgentTypeDesc | DB1: =IFERROR(VLOOKUP(DB3,Sheet2!$A$1:$A$135,1,FALSE),"Ignore Field") -> NomineeName | DC1: =IFERROR(VLOOKUP(DC3,Sheet2!$A$1:$A$135,1,FALSE),"Ignore Field") -> Relationship | DD1: =IFERROR(VLOOKUP(DD3,Sheet2!$A$1:$A$135,1,FALSE),"Ignore Field") -> PercentageShare | ... ED1: =IFERROR(VLOOKUP(ED3,Sheet2!$A$1:$A$135,1,FALSE),"Ignore Field") -> BranchDesc
A3: AgentCode | B3: AgentName | C3: BusinessName | D3: FirstName | E3: MiddleName | F3: LastName | G3: Prefix | H3: Suffix | I3: DoB | J3: Nationality | K3: PreferredLanguage | L3: ChannelCode | M3: SubChannelCode | N3: Designation | O3: AgentLevel | P3: StaffCode | Q3: Supervisor_Code | R3: ContractedDate | S3: AgentStatusCode | T3: StatusDate | U3: IsLicensed | V3: MaskedPanNumber | W3: AadhaarNumber | X3: IrdaLicenseNumber | Y3: GstNumber | Z3: CreatedBy | AA3: CreatedDate | AB3: RowVersion | AC3: IsActive | AD3: ApplicationDocketNo | AE3: Father_Husband_Nm | AF3: EmployeeCode | AG3: StartDate | AH3: PanAadharLinkFlag | AI3: Sec206abFlag | AJ3: PackageID | AK3: TaxStatus | AL3: StateEid | AM3: OccupationCode | AN3: URN | AO3: AdditionalComment | AP3: AppointmentDate | AQ3: IncorporationDate | AR3: CnctPersonDesig | AS3: CnctPersonMobileNo | AT3: CnctPersonEmail | AU3: CnctPersonName | AV3: CMSAgentType | AW3: ServiceTaxNo | AX3: UlipFlag | AY3: TrainingGroupType | AZ3: Ifs | BA3: RefresherTrainingCompleted | BB3: IsMigrated | BC3: MainPartnerClientCode | BD3: AgentMaincodevwEid | BE3: RegistrationDate | BF3: Vertical | BG3: BranchCode | BH3: BranchName | BI3: IC36TrngCompletionDate | BJ3: STrngCompletionDate | BK3: ConfirmationDate | BL3: FgRockStarTrainingDate | BM3: IncrementDate | BN3: LastPromotionDate | BO3: HRDoj | BP3: FgValueTrngDate | BQ3: HSecPolicyTrngDate | BR3: ITSecPolicyTrngDate | BS3: NPSTrngCompletionDate | BT3: WhistleBlowerTrngDate | BU3: GovPolicyTrngDate | BV3: InductionTrngDate | BW3: LastWorkingDate | BX3: LicenseNo | BY3: LicenseType | BZ3: LicenseIssueDate | CA3: LicenseExpiryDate | CB3: LicenseStatus | CC3: AddressLine1 | CD3: AddressLine2 | CE3: AddressLine3 | CF3: City | CG3: Pin | CH3: Landmark | CI3: AgentClassDesc | CJ3: BankAccTypeDesc | CK3: GenderDesc | CL3: TitleDesc | CM3: ChannelDesc | CN3: SubChannelDesc | CO3: OccupationDesc | CP3: AgentTypeCatDesc | CQ3: MaritalStatusDesc | CR3: EducationDesc | CS3: StateDesc | CT3: CountryDesc | CU3: DesignationCodeDesc | CV3: LocationCodeDesc | CW3: AgentTypeCodeDesc | CX3: AgentSubTypeCodeDesc | CY3: CandidateTypeDesc | CZ3: CommissionClassDesc | DA3: AgentTypeDesc | DB3: NomineeName | DC3: Relationship | DD3: PercentageShare | DE3: NomineeAge | DF3: AccountHolderName | DG3: AccountNumber | DH3: IFSC | DI3: MICR | DJ3: BankName | DK3: BankAccBranchName | DL3: AccountType | DM3: ActiveSince | DN3: FactoringHouse | DO3: PreferredPaymentMode | DP3: DateOfBirth | DQ3: PanNumber | DR3: Email | DS3: MobileNo | DT3: WorkContactNo | DU3: ResidenceContactNo | DV3: BloodGroup | DW3: BirthPlace | DX3: MartialStatus | DY3: EducationCode | DZ3: EducationLevel | EA3: WorkProfile | EB3: AnnualIncome | EC3: WorkExpMonths | ED3: BranchDesc
B4: Quon Brock | C4: Quon Brock | D4: Quon | E4: A | F4: Brock | G4: Mr | I4: 24796 | J4: Indian | K4: English | Q4: AG2602191401001 | R4: 45373 | S4: Active | T4: 46054 | U4: TRUE | V4: KPWHY0210T | W4: 810344529012 | X4: IRDA00007 | Y4: GST00007 | Z4: System | AA4: 46056 | AC4: TRUE | AD4: Docket7 | AE4: Isaias Hull | AF4: EMP7 | AG4: 45028 | AH4: TRUE | AI4: TRUE | AK4: Taxable | AL4: State5 | AM4: 1 | AN4: URN7 | AO4: No Comment | AP4: 46044 | AQ4: 44158 | AR4: Manager | AS4: 9847012345 | AT4: priya.nair.kerala@outlook.com | AU4: priya nair | AV4: CMS3 | AW4: ST7 | AX4: FALSE | AY4: General | AZ4: IFS3 | BA4: TRUE | BB4: FALSE | BC4: Client7 | BD4: AM7 | BE4: 45716 | BF4: Healthcare | BG4: BR1 | BH4: Branch1 | BI4: 44206 | BJ4: 44547 | BK4: 44871 | BL4: 45898 | BM4: 45420 | BN4: 44050 | BO4: 45716 | BP4: 45789 | BQ4: 45478 | BR4: 44157 | BS4: 45645 | BT4: 43864 | BU4: 44372 | BV4: 45079 | BW4: 45421 | BX4: LIC007 | BY4: Permanent | BZ4: 45860 | CA4: 46231 | CB4: Active | CC4: Omkar Residency | CD4: Link Road | CE4: Andheri West | CF4: Mumbai | CG4: 400053 | CH4: Near | CI4: Master Individual Agent (MIA) | CJ4: Savings Account | CK4: Female | CL4: Mr. | CM4: LeslieV | CO4: Salaried Employee | CP4: Individual | CQ4: Married | CR4: Graduate (Bachelors) | CS4: Maharashtra | CT4: India | CU4: Zonal Head | CV4: Zonal Office | CW4: Sales | CX4: Field Sales | CY4: Junior | CZ4: Class 1 | DA4: Type 1 | DB4: Mckenna Cervantes | DC4: Brother | DD4: 10 | DE4: 32 | DF4: Bell Murphy | DG4: 829104573612 | DH4: AXIS0000790 | DI4: 500001004 | DJ4: HDFC Bank | DK4: Mumbai | DL4: 2 | DM4: 43911 | DN4: HDFC Factoring | DO4: 1 | DP4: 32343 | DQ4: PQRST3456U | DR4: vijay.rao@email.com | DS4: 9988776657 | DT4: 4060001234 | DU4: 4060004321 | DV4: AB+ | DW4: Mumbai | DX4: 2 | DY4: 5 | DZ4: Graduate | EA4: Sales Executive | EB4: 1200000 | EC4: 156 | ED4: East
B5: Denise May | C5: Denise May | D5: Denise | F5: May | G5: Mr | I5: 18115 | J5: Indian | K5: English | Q5: AG2602191401001 | R5: 44136 | S5: Active | T5: 46054 | U5: TRUE | V5: FGKNN4725Z | W5: 456712348901 | X5: IRDA00008 | Y5: GST00008 | Z5: System | AA5: 46056 | AC5: TRUE | AD5: Docket8 | AE5: Andi Perkins | AF5: EMP8 | AG5: 45678 | AH5: TRUE | AI5: TRUE | AK5: Taxable | AL5: State5 | AM5: 1 | AN5: URN8 | AO5: No Comment | AP5: 46036 | AQ5: 44158 | AR5: Manager | AS5: 7736088990 | AT5: rahul_jain1990@yahoo.co.in | AU5: rahul jain | AV5: CMS4 | AW5: ST8 | AX5: FALSE | AY5: General | AZ5: IFS4 | BA5: TRUE | BB5: FALSE | BC5: Client8 | BD5: AM8 | BE5: 45731 | BF5: Healthcare | BG5: BR1 | BH5: Branch1 | BI5: 44207 | BJ5: 44548 | BK5: 44872 | BL5: 45899 | BM5: 45421 | BN5: 44051 | BO5: 45731 | BP5: 45790 | BQ5: 45479 | BR5: 44158 | BS5: 45646 | BT5: 43865 | BU5: 44373 | BV5: 45080 | BW5: 45422 | BX5: LIC008 | BY5: Permanent | BZ5: 45423 | CA5: 46330 | CB5: Active | CC5: Sai Apartment | CD5: Tilak Nagar | CE5: Chembur | CF5: Mumbai | CG5: 400089 | CH5: Near | CI5: Master Individual Agent (MIA) | CJ5: Savings Account | CK5: Female | CL5: Mr. | CM5: LeslieV | CO5: Salaried Employee | CP5: Individual | CQ5: Married | CR5: Graduate (Bachelors) | CS5: Maharashtra | CT5: India | CU5: Zonal Head | CV5: Zonal Office | CW5: Sales | CX5: Field Sales | CY5: Junior | CZ5: Class 1 | DA5: Type 1 | DB5: Mckenna Cervantes | DC5: Brother | DD5: 10 | DE5: 32 | DF5: Bell Murphy | DG5: 829104573612 | DH5: AXIS0000790 | DI5: 500001004 | DJ5: HDFC Bank | DK5: Mumbai | DL5: 2 | DM5: 43911 | DN5: HDFC Factoring | DO5: 1 | DP5: 32343 | DQ5: PQRST3456U | DR5: vijay.rao@email.com | DS5: 9988776657 | DT5: 4060001234 | DU5: 4060004321 | DV5: AB+ | DW5: Mumbai | DX5: 2 | DY5: 5 | DZ5: Graduate | EA5: Sales Executive | EB5: 1200000 | EC5: 156 | ED5: West
B6: Zachary Ellison | C6: Zachary Ellison | D6: Zachary | F6: Ellison | G6: Mr | I6: 26328 | J6: Indian | K6: English | Q6: AG2602191401001 | R6: 46161 | S6: Active | T6: 46054 | U6: TRUE | V6: HYHGI3531C | W6: 773200193345 | X6: IRDA00009 | Y6: GST00009 | Z6: System | AA6: 46056 | AC6: TRUE | AD6: Docket9 | AE6: Kyrie Good | AF6: EMP9 | AG6: 44530 | AH6: FALSE | AI6: TRUE | AK6: Taxable | AL6: State5 | AM6: 1 | AN6: URN9 | AO6: No Comment | AP6: 46052 | AQ6: 44158 | AR6: Manager | AS6: 6235109876 | AT6: sneha_singh.mumbai@gmail.com | AU6: sneha singh | AV6: CMS5 | AW6: ST9 | AX6: FALSE | AY6: General | AZ6: IFS5 | BA6: TRUE | BB6: FALSE | BC6: Client9 | BD6: AM9 | BE6: 45750 | BF6: Healthcare | BG6: BR1 | BH6: Branch1 | BI6: 44208 | BJ6: 44549 | BK6: 44873 | BL6: 45900 | BM6: 45422 | BN6: 44052 | BO6: 45750 | BP6: 45791 | BQ6: 45480 | BR6: 44159 | BS6: 45647 | BT6: 43866 | BU6: 44374 | BV6: 45081 | BW6: 45423 | BX6: LIC009 | BY6: Permanent | BZ6: 45663 | CA6: 46044 | CB6: Active | CC6: Chawl No 3 | CD6: Gokhale Road | CE6: Dadar West | CF6: Mumbai | CG6: 400028 | CH6: Near | CI6: Master Individual Agent (MIA) | CJ6: Savings Account | CK6: Female | CL6: Mr. | CM6: LeslieV | CO6: Salaried Employee | CP6: Individual | CQ6: Married | CR6: Graduate (Bachelors) | CS6: Maharashtra | CT6: India | CU6: Zonal Head | CV6: Zonal Office | CW6: Sales | CX6: Field Sales | CY6: Junior | CZ6: Class 1 | DA6: Type 1 | DB6: Mckenna Cervantes | DC6: Brother | DD6: 10 | DE6: 32 | DF6: Bell Murphy | DG6: 829104573612 | DH6: AXIS0000790 | DI6: 500001004 | DJ6: HDFC Bank | DK6: Mumbai | DL6: 2 | DM6: 43911 | DN6: HDFC Factoring | DO6: 1 | DP6: 32343 | DQ6: PQRST3456U | DR6: vijay.rao@email.com | DS6: 9988776657 | DT6: 4060001234 | DU6: 4060004321 | DV6: AB+ | DW6: Mumbai | DX6: 2 | DY6: 5 | DZ6: Graduate | EA6: Sales Executive | EB6: 1200000 | EC6: 156 | ED6: North
B7: Merrill Coleman | C7: Merrill Coleman | D7: Merrill | F7: Coleman | G7: Mr | I7: 20259 | J7: Indian | K7: English | Q7: AG2602191401001 | R7: 45199 | S7: Active | T7: 46054 | U7: TRUE | V7: HWULX6881T | W7: 109855672210 | X7: IRDA00010 | Y7: GST00010 | Z7: System | AA7: 46056 | AC7: TRUE | AD7: Docket10 | AE7: Nathalia Rocha | AF7: EMP10 | AG7: 45488 | AH7: FALSE | AI7: TRUE | AK7: Taxable | AL7: State5 | AM7: 1 | AN7: URN10 | AO7: No Comment | AP7: 46024 | AQ7: 44158 | AR7: Manager | AS7: 9447056789 | AT7: amit.verma.hyd@gmail.com | AU7: amit verma | AV7: CMS6 | AW7: ST10 | AX7: FALSE | AY7: General | AZ7: IFS6 | BA7: TRUE | BB7: FALSE | BC7: Client10 | BD7: AM10 | BE7: 45769 | BF7: Healthcare | BG7: BR1 | BH7: Branch1 | BI7: 44209 | BJ7: 44550 | BK7: 44874 | BL7: 45901 | BM7: 45423 | BN7: 44053 | BO7: 45769 | BP7: 45792 | BQ7: 45481 | BR7: 44160 | BS7: 45648 | BT7: 43867 | BU7: 44375 | BV7: 45082 | BW7: 45424 | BX7: LIC010 | BY7: Permanent | BZ7: 45501 | CA7: 46161 | CB7: Active | CC7: Sea View Building | CD7: Worli Sea Face | CE7: Worli | CF7: Mumbai | CG7: 400030 | CH7: Near | CI7: Master Individual Agent (MIA) | CJ7: Savings Account | CK7: Female | CL7: Mr. | CM7: LeslieV | CO7: Salaried Employee | CP7: Individual | CQ7: Married | CR7: Graduate (Bachelors) | CS7: Maharashtra | CT7: India | CU7: Zonal Head | CV7: Zonal Office | CW7: Sales | CX7: Field Sales | CY7: Junior | CZ7: Class 1 | DA7: Type 1 | DB7: Mckenna Cervantes | DC7: Brother | DD7: 10 | DE7: 32 | DF7: Bell Murphy | DG7: 829104573612 | DH7: AXIS0000790 | DI7: 500001004 | DJ7: HDFC Bank | DK7: Mumbai | DL7: 2 | DM7: 43911 | DN7: HDFC Factoring | DO7: 1 | DP7: 32343 | DQ7: PQRST3456U | DR7: vijay.rao@email.com | DS7: 9988776657 | DT7: 4060001234 | DU7: 4060004321 | DV7: AB+ | DW7: Mumbai | DX7: 2 | DY7: 5 | DZ7: Graduate | EA7: Sales Executive | EB7: 1200000 | EC7: 156 | ED7: South

Sheet Sheet3
A1: Column Name | B1: # | C1: Data type | D1: Identity | E1: Collation | F1: Not Null | G1: Default | H1: Comment
A2: agent_id | B2: 1 | C2: int4 | D2: Always | E2: [NULL] | F2: Mandatory | G2: [NULL] | H2: [NULL]
A3: agent_code | B3: 2 | C3: varchar(50) | D3: [NULL] | E3: default | F3: Mandatory | G3: [NULL] | H3: [NULL]
A4: agent_name | B4: 5 | C4: varchar(150) | D4: [NULL] | E4: default | F4: FALSE | G4: [NULL] | H4: [NULL]
A5: business_name | B5: 6 | C5: varchar(300) | D5: [NULL] | E5: default | F5: FALSE | G5: [NULL] | H5: [NULL]
A6: first_name | B6: 7 | C6: varchar(150) | D6: [NULL] | E6: default | F6: FALSE | G6: [NULL] | H6: [NULL]
A7: middle_name | B7: 8 | C7: varchar(150) | D7: [NULL] | E7: default | F7: FALSE | G7: [NULL] | H7: [NULL]
A8: last_name | B8: 9 | C8: varchar(150) | D8: [NULL] | E8: default | F8: FALSE | G8: [NULL] | H8: [NULL]
A9: prefix | B9: 10 | C9: varchar(20) | D9: [NULL] | E9: default | F9: FALSE | G9: [NULL] | H9: [NULL]
A10: suffix | B10: 11 | C10: varchar(20) | D10: [NULL] | E10: default | F10: FALSE | G10: [NULL] | H10: [NULL]
A11: dob | B11: 13 | C11: date | D11: [NULL] | E11: [NULL] | F11: FALSE | G11: [NULL] | H11: [NULL]
A12: nationality | B12: 14 | C12: varchar(40) | D12: [NULL] | E12: default | F12: FALSE | G12: [NULL] | H12: [NULL]
A13: preferred_language | B13: 16 | C13: varchar(22) | D13: [NULL] | E13: default | F13: FALSE | G13: [NULL] | H13: [NULL]
A14: agent_level | B14: 20 | C14: varchar(20) | D14: [NULL] | E14: default | F14: FALSE | G14: [NULL] | H14: [NULL]
A15: staff_code | B15: 22 | C15: varchar(20) | D15: [NULL] | E15: default | F15: FALSE | G15: [NULL] | H15: [NULL]
... A18: status_date | B18: 26 | C18: date | D18: [NULL] | E18: [NULL] | F18: FALSE | G18: [NULL] | H18: [NULL]
A19: is_licensed | B19: 27 | C19: bool | D19: [NULL] | E19: [NULL] | F19: Mandatory | G19: [NULL] | H19: [NULL]
A20: pan_number | B20: 28 | C20: varchar(40) | D20: [NULL] | E20: default | F20: FALSE | G20: [NULL] | H20: [NULL]
A21: aadhaar_number | B21: 29 | C21: varchar(40) | D21: [NULL] | E21: default | F21: FALSE | G21: [NULL] | H21: [NULL]
A22: irda_license_number | B22: 30 | C22: varchar(40) | D22: [NULL] | E22: default | F22: FALSE | G22: [NULL] | H22: [NULL]
A23: gst_number | B23: 31 | C23: varchar(100) | D23: [NULL] | E23: default | F23: FALSE | G23: [NULL] | H23: [NULL]
A24: created_by | B24: 32 | C24: varchar(100) | D24: [NULL] | E24: default | F24: Mandatory | G24: [NULL] | H24: [NULL]
A25: created_date | B25: 33 | C25: timestamp | D25: [NULL] | E25: [NULL] | F25: Mandatory | G25: [NULL] | H25: [NULL]
A26: modified_by | B26: 34 | C26: varchar(100) | D26: [NULL] | E26: default | F26: FALSE | G26: [NULL] | H26: [NULL]
A27: modified_date | B27: 35 | C27: timestamp | D27: [NULL] | E27: [NULL] | F27: FALSE | G27: [NULL] | H27: [NULL]
A28: rowversion | B28: 36 | C28: int4 | D28: [NULL] | E28: [NULL] | F28: FALSE | G28: [NULL] | H28: [NULL]
A29: supervisor_id | B29: 38 | C29: int4 | D29: [NULL] | E29: [NULL] | F29: FALSE | G29: [NULL] | H29: [NULL]
A30: is_active | B30: 39 | C30: bool | D30: [NULL] | E30: [NULL] | F30: Mandatory | G30: TRUE | H30: [NULL]
A31: email | B31: 40 | C31: varchar(50) | D31: [NULL] | E31: default | F31: FALSE | G31: [NULL] | H31: [NULL]
A32: mobileno | B32: 41 | C32: varchar(20) | D32: [NULL] | E32: default | F32: FALSE | G32: [NULL] | H32: [NULL]
A33: applicationdocketno | B33: 43 | C33: varchar(100) | D33: [NULL] | E33: default | F33: FALSE | G33: [NULL] | H33: [NULL]
A34: father_husband_nm | B34: 45 | C34: varchar(200) | D34: [NULL] | E34: default | F34: FALSE | G34: [NULL] | H34: [NULL]
A35: employeecode | B35: 48 | C35: varchar(50) | D35: [NULL] | E35: default | F35: FALSE | G35: [NULL] | H35: [NULL]
A36: startdate | B36: 49 | C36: timestamp | D36: [NULL] | E36: [NULL] | F36: FALSE | G36: [NULL] | H36: [NULL]
A37: panaadharlinkflag | B37: 50 | C37: bool | D37: [NULL] | E37: [NULL] | F37: Mandatory | G37: FALSE | H37: [NULL]
A38: sec206abflag | B38: 51 | C38: bool | D38: [NULL] | E38: [NULL] | F38: Mandatory | G38: FALSE | H38: [NULL]
A39: taxstatus | B39: 53 | C39: varchar(50) | D39: [NULL] | E39: default | F39: FALSE | G39: [NULL] | H39: [NULL]
A40: stateeid | B40: 54 | C40: varchar(50) | D40: [NULL] | E40: default | F40: FALSE | G40: [NULL] | H40: [NULL]
A41: urn | B41: 57 | C41: varchar(50) | D41: [NULL] | E41: default | F41: FALSE | G41: [NULL] | H41: [NULL]
A42: additionalcomment | B42: 58 | C42: varchar(200) | D42: [NULL] | E42: default | F42: FALSE | G42: [NULL] | H42: [NULL]
...

Sheet Sheet2
A1: AgentId
A2: AgentName
A3: BusinessName
A4: FirstName
A5: MiddleName
A6: LastName
A7: Prefix
A8: Suffix
A9: DoB
A10: Nationality
A11: PreferredLanguage
A12: AgentLevel
... A135: BranchDesc
